Workbook
Name Slicer_location_type1: #N/A

Sheet rawdata
A1: location_type | B1: cuisine_type | C1: restaurant_size | D1: has_parking | E1: has_delivery | F1: seating_capacity | G1: avg_meal_price | H1: years_in_business | I1: staff_count | J1: marketing_spend | K1: customer_rating | L1: location_type_Strip_Mall | M1: location_type_Mall | N1: location_type_Downtown | O1: cuisine_type_Asian | P1: cuisine_type_American | Q1: cuisine_type_Italian | R1: cuisine_type_Mexican | S1: restaurant_size_Small | T1: restaurant_size_Medium | U1: has_parking_Yes | V1: has_delivery_Yes | W1: monthly_revenue | X1: ln(monthly_revenue)
A2: Strip_Mall | B2: Asian | C2: Large | D2: Yes | E2: Yes | F2: 48 | G2: 23.79 | H2: 13.1 | I2: 11 | J2: 1380 | K2: 4.73 | L2: =IF(rawdata!$A2="Strip_Mall", 1, 0) -> 1 | M2: =IF(rawdata!$A2="Mall", 1, 0) -> 0 | N2: =IF(rawdata!$A2="Downtown", 1, 0) -> 0 | O2: =IF(rawdata!$B2="Asian", 1, 0) -> 1 | P2: =IF(rawdata!$B2="American", 1, 0) -> 0 | Q2: =IF(rawdata!$B2="Italian", 1, 0) -> 0 | R2: =IF(rawdata!$B2="Mexican", 1, 0) -> 0 | S2: =IF(rawdata!$C2="Small", 1, 0) -> 0 | T2: =IF(rawdata!$C2="Medium", 1, 0) -> 0 | U2: =IF(rawdata!$D2="Yes", 1, 0) -> 1 | V2: =IF(rawdata!$E2="Yes", 1, 0) -> 1 | W2: 83079 | X2: =LN(W2) -> 11.327547
A3: Strip_Mall | B3: American | C3: Small | D3: Yes | E3: Yes | F3: 76 | G3: 11.34 | H3: 14.8 | I3: 18 | J3: 2439 | K3: 4.75 | L3: =IF(rawdata!$A3="Strip_Mall", 1, 0) -> 1 | M3: =IF(rawdata!$A3="Mall", 1, 0) -> 0 | N3: =IF(rawdata!$A3="Downtown", 1, 0) -> 0 | O3: =IF(rawdata!$B3="Asian", 1, 0) -> 0 | P3: =IF(rawdata!$B3="American", 1, 0) -> 1 | Q3: =IF(rawdata!$B3="Italian", 1, 0) -> 0 | R3: =IF(rawdata!$B3="Mexican", 1, 0) -> 0 | S3: =IF(rawdata!$C3="Small", 1, 0) -> 1 | T3: =IF(rawdata!$C3="Medium", 1, 0) -> 0 | U3: =IF(rawdata!$D3="Yes", 1, 0) -> 1 | V3: =IF(rawdata!$E3="Yes", 1, 0) -> 1 | W3: 31459 | X3: =LN(W3) -> 10.35644
A4: Suburban | B4: American | C4: Large | D4: Yes | E4: No | F4: 45 | G4: 23.86 | H4: 6.5 | I4: 22 | J4: 1918 | K4: 4.54 | L4: =IF(rawdata!$A4="Strip_Mall", 1, 0) -> 0 | M4: =IF(rawdata!$A4="Mall", 1, 0) -> 0 | N4: =IF(rawdata!$A4="Downtown", 1, 0) -> 0 | O4: =IF(rawdata!$B4="Asian", 1, 0) -> 0 | P4: =IF(rawdata!$B4="American", 1, 0) -> 1 | Q4: =IF(rawdata!$B4="Italian", 1, 0) -> 0 | R4: =IF(rawdata!$B4="Mexican", 1, 0) -> 0 | S4: =IF(rawdata!$C4="Small", 1, 0) -> 0 | T4: =IF(rawdata!$C4="Medium", 1, 0) -> 0 | U4: =IF(rawdata!$D4="Yes", 1, 0) -> 1 | V4: =IF(rawdata!$E4="Yes", 1, 0) -> 0 | W4: 133797 | X4: =LN(W4) -> 11.804079
A5: Strip_Mall | B5: Italian | C5: Small | D5: Yes | E5: Yes | F5: 80 | G5: 11.02 | H5: 23.2 | I5: 21 | J5: 3833 | K5: 4.34 | L5: =IF(rawdata!$A5="Strip_Mall", 1, 0) -> 1 | M5: =IF(rawdata!$A5="Mall", 1, 0) -> 0 | N5: =IF(rawdata!$A5="Downtown", 1, 0) -> 0 | O5: =IF(rawdata!$B5="Asian", 1, 0) -> 0 | P5: =IF(rawdata!$B5="American", 1, 0) -> 0 | Q5: =IF(rawdata!$B5="Italian", 1, 0) -> 1 | R5: =IF(rawdata!$B5="Mexican", 1, 0) -> 0 | S5: =IF(rawdata!$C5="Small", 1, 0) -> 1 | T5: =IF(rawdata!$C5="Medium", 1, 0) -> 0 | U5: =IF(rawdata!$D5="Yes", 1, 0) -> 1 | V5: =IF(rawdata!$E5="Yes", 1, 0) -> 1 | W5: 41739 | X5: =LN(W5) -> 10.639191
A6: Mall | B6: Mexican | C6: Medium | D6: No | E6: No | F6: 107 | G6: 14.37 | H6: 0.7 | I6: 28 | J6: 2714 | K6: 3.89 | L6: =IF(rawdata!$A6="Strip_Mall", 1, 0) -> 0 | M6: =IF(rawdata!$A6="Mall", 1, 0) -> 1 | N6: =IF(rawdata!$A6="Downtown", 1, 0) -> 0 | O6: =IF(rawdata!$B6="Asian", 1, 0) -> 0 | P6: =IF(rawdata!$B6="American", 1, 0) -> 0 | Q6: =IF(rawdata!$B6="Italian", 1, 0) -> 0 | R6: =IF(rawdata!$B6="Mexican", 1, 0) -> 1 | S6: =IF(rawdata!$C6="Small", 1, 0) -> 0 | T6: =IF(rawdata!$C6="Medium", 1, 0) -> 1 | U6: =IF(rawdata!$D6="Yes", 1, 0) -> 0 | V6: =IF(rawdata!$E6="Yes", 1, 0) -> 0 | W6: 67946 | X6: =LN(W6) -> 11.126469
A7: Downtown | B7: Mexican | C7: Small | D7: No | E7: Yes | F7: 49 | G7: 27.5 | H7: 0.8 | I7: 16 | J7: 7233 | K7: 4.48 | L7: =IF(rawdata!$A7="Strip_Mall", 1, 0) -> 0 | M7: =IF(rawdata!$A7="Mall", 1, 0) -> 0 | N7: =IF(rawdata!$A7="Downtown", 1, 0) -> 1 | O7: =IF(rawdata!$B7="Asian", 1, 0) -> 0 | P7: =IF(rawdata!$B7="American", 1, 0) -> 0 | Q7: =IF(rawdata!$B7="Italian", 1, 0) -> 0 | R7: =IF(rawdata!$B7="Mexican", 1, 0) -> 1 | S7: =IF(rawdata!$C7="Small", 1, 0) -> 1 | T7: =IF(rawdata!$C7="Medium", 1, 0) -> 0 | U7: =IF(rawdata!$D7="Yes", 1, 0) -> 0 | V7: =IF(rawdata!$E7="Yes", 1, 0) -> 1 | W7: 78876 | X7: =LN(W7) -> 11.275632
A8: Mall | B8: Fast_Food | C8: Large | D8: Yes | E8: No | F8: 57 | G8: 15.68 | H8: 0.5 | I8: 19 | J8: 5105 | K8: 3.73 | L8: =IF(rawdata!$A8="Strip_Mall", 1, 0) -> 0 | M8: =IF(rawdata!$A8="Mall", 1, 0) -> 1 | N8: =IF(rawdata!$A8="Downtown", 1, 0) -> 0 | O8: =IF(rawdata!$B8="Asian", 1, 0) -> 0 | P8: =IF(rawdata!$B8="American", 1, 0) -> 0 | Q8: =IF(rawdata!$B8="Italian", 1, 0) -> 0 | R8: =IF(rawdata!$B8="Mexican", 1, 0) -> 0 | S8: =IF(rawdata!$C8="Small", 1, 0) -> 0 | T8: =IF(rawdata!$C8="Medium", 1, 0) -> 0 | U8: =IF(rawdata!$D8="Yes", 1, 0) -> 1 | V8: =IF(rawdata!$E8="Yes", 1, 0) -> 0 | W8: 126677 | X8: =LN(W8) -> 11.749396
A9: Suburban | B9: Fast_Food | C9: Small | D9: Yes | E9: Yes | F9: 76 | G9: 24.63 | H9: 11.5 | I9: 23 | J9: 5779 | K9: 3.48 | L9: =IF(rawdata!$A9="Strip_Mall", 1, 0) -> 0 | M9: =IF(rawdata!$A9="Mall", 1, 0) -> 0 | N9: =IF(rawdata!$A9="Downtown", 1, 0) -> 0 | O9: =IF(rawdata!$B9="Asian", 1, 0) -> 0 | P9: =IF(rawdata!$B9="American", 1, 0) -> 0 | Q9: =IF(rawdata!$B9="Italian", 1, 0) -> 0 | R9: =IF(rawdata!$B9="Mexican", 1, 0) -> 0 | S9: =IF(rawdata!$C9="Small", 1, 0) -> 1 | T9: =IF(rawdata!$C9="Medium", 1, 0) -> 0 | U9: =IF(rawdata!$D9="Yes", 1, 0) -> 1 | V9: =IF(rawdata!$E9="Yes", 1, 0) -> 1 | W9: 77981 | X9: =LN(W9) -> 11.26422
A10: Mall | B10: Asian | C10: Medium | D10: Yes | E10: Yes | F10: 50 | G10: 15.67 | H10: 2.6 | I10: 14 | J10: 1841 | K10: 3.12 | L10: =IF(rawdata!$A10="Strip_Mall", 1, 0) -> 0 | M10: =IF(rawdata!$A10="Mall", 1, 0) -> 1 | N10: =IF(rawdata!$A10="Downtown", 1, 0) -> 0 | O10: =IF(rawdata!$B10="Asian", 1, 0) -> 1 | P10: =IF(rawdata!$B10="American", 1, 0) -> 0 | Q10: =IF(rawdata!$B10="Italian", 1, 0) -> 0 | R10: =IF(rawdata!$B10="Mexican", 1, 0) -> 0 | S10: =IF(rawdata!$C10="Small", 1, 0) -> 0 | T10: =IF(rawdata!$C10="Medium", 1, 0) -> 1 | U10: =IF(rawdata!$D10="Yes", 1, 0) -> 1 | V10: =IF(rawdata!$E10="Yes", 1, 0) -> 1 | W10: 50296 | X10: =LN(W10) -> 10.825681
A11: Mall | B11: American | C11: Medium | D11: Yes | E11: Yes | F11: 65 | G11: 8 | H11: 2.6 | I11: 16 | J11: 1107 | K11: 3.83 | L11: =IF(rawdata!$A11="Strip_Mall", 1, 0) -> 0 | M11: =IF(rawdata!$A11="Mall", 1, 0) -> 1 | N11: =IF(rawdata!$A11="Downtown", 1, 0) -> 0 | O11: =IF(rawdata!$B11="Asian", 1, 0) -> 0 | P11: =IF(rawdata!$B11="American", 1, 0) -> 1 | Q11: =IF(rawdata!$B11="Italian", 1, 0) -> 0 | R11: =IF(rawdata!$B11="Mexican", 1, 0) -> 0 | S11: =IF(rawdata!$C11="Small", 1, 0) -> 0 | T11: =IF(rawdata!$C11="Medium", 1, 0) -> 1 | U11: =IF(rawdata!$D11="Yes", 1, 0) -> 1 | V11: =IF(rawdata!$E11="Yes", 1, 0) -> 1 | W11: 38302 | X11: =LN(W11) -> 10.553257
A12: Downtown | B12: Asian | C12: Small | D12: Yes | E12: Yes | F12: 97 | G12: 11.21 | H12: 0.5 | I12: 19 | J12: 14299 | K12: 4.65 | L12: =IF(rawdata!$A12="Strip_Mall", 1, 0) -> 0 | M12: =IF(rawdata!$A12="Mall", 1, 0) -> 0 | N12: =IF(rawdata!$A12="Downtown", 1, 0) -> 1 | O12: =IF(rawdata!$B12="Asian", 1, 0) -> 1 | P12: =IF(rawdata!$B12="American", 1, 0) -> 0 | Q12: =IF(rawdata!$B12="Italian", 1, 0) -> 0 | R12: =IF(rawdata!$B12="Mexican", 1, 0) -> 0 | S12: =IF(rawdata!$C12="Small", 1, 0) -> 1 | T12: =IF(rawdata!$C12="Medium", 1, 0) -> 0 | U12: =IF(rawdata!$D12="Yes", 1, 0) -> 1 | V12: =IF(rawdata!$E12="Yes", 1, 0) -> 1 | W12: 58721 | X12: =LN(W12) -> 10.980553
A13: Mall | B13: Fast_Food | C13: Small | D13: No | E13: Yes | F13: 99 | G13: 9.29 | H13: 0.5 | I13: 20 | J13: 4955 | K13: 3.64 | L13: =IF(rawdata!$A13="Strip_Mall", 1, 0) -> 0 | M13: =IF(rawdata!$A13="Mall", 1, 0) -> 1 | N13: =IF(rawdata!$A13="Downtown", 1, 0) -> 0 | O13: =IF(rawdata!$B13="Asian", 1, 0) -> 0 | P13: =IF(rawdata!$B13="American", 1, 0) -> 0 | Q13: =IF(rawdata!$B13="Italian", 1, 0) -> 0 | R13: =IF(rawdata!$B13="Mexican", 1, 0) -> 0 | S13: =IF(rawdata!$C13="Small", 1, 0) -> 1 | T13: =IF(rawdata!$C13="Medium", 1, 0) -> 0 | U13: =IF(rawdata!$D13="Yes", 1, 0) -> 0 | V13: =IF(rawdata!$E13="Yes", 1, 0) -> 1 | W13: 38720 | X13: =LN(W13) -> 10.564112
... A101: Mall | B101: Fast_Food | C101: Medium | D101: Yes | E101: Yes | F101: 109 | G101: 22.37 | H101: 0.6 | I101: 26 | J101: 613 | K101: 4.54 | L101: =IF(rawdata!$A101="Strip_Mall", 1, 0) -> 0 | M101: =IF(rawdata!$A101="Mall", 1, 0) -> 1 | N101: =IF(rawdata!$A101="Downtown", 1, 0) -> 0 | O101: =IF(rawdata!$B101="Asian", 1, 0) -> 0 | P101: =IF(rawdata!$B101="American", 1, 0) -> 0 | Q101: =IF(rawdata!$B101="Italian", 1, 0) -> 0 | R101: =IF(rawdata!$B101="Mexican", 1, 0) -> 0 | S101: =IF(rawdata!$C101="Small", 1, 0) -> 0 | T101: =IF(rawdata!$C101="Medium", 1, 0) -> 1 | U101: =IF(rawdata!$D101="Yes", 1, 0) -> 1 | V101: =IF(rawdata!$E101="Yes", 1, 0) -> 1 | W101: 104830 | X101: =LN(W101) -> 11.560095

Sheet Dashboard
A1: Restaurant Revenue Dashboard
AL12: Column Chart
AL13: Row Labels | AM13: Sum of monthly_revenue
AL14: Strip_Mall | AM14: 1283916
AL15: Mexican | AM15: 29283
AL16: Italian | AM16: 197751
AL17: American | AM17: 259525
AL18: Fast_Food | AM18: 276240
AL19: Asian | AM19: 521117
AL20: Grand Total | AM20: 1283916
Y29: ZW

Sheet Model_1_Quantitative
A1: Step 1.1 | B1: EDA Analysis for Quantitative data independent variables
A3: seating_capacity | C3: avg_meal_price | E3: years_in_business | G3: staff_count | I3: marketing_spend | K3: customer_rating
A5: Mean | B5: 74.01 | C5: Mean | D5: 18.3669 | E5: Mean | F5: 5.375 | G5: Mean | H5: 19.79 | I5: Mean | J5: 4458.7 | K5: Mean | L5: 4.2279
A6: Standard Error | B6: 2.2920369 | C6: Standard Error | D6: 0.7237699 | E6: Standard Error | F6: 0.5236939 | G6: Standard Error | H6: 0.39473684 | I6: Standard Error | J6: 425.90035 | K6: Standard Error | L6: 0.053051775
A7: Median | B7: 75.5 | C7: Median | D7: 16.555 | E7: Median | F7: 3.6 | G7: Median | H7: 20 | I7: Median | J7: 2753.5 | K7: Median | L7: 4.36
A8: Mode | B8: 76 | C8: Mode | D8: 8 | E8: Mode | F8: 0.5 | G8: Mode | H8: 20 | I8: Mode | J8: 500 | K8: Mode | L8: 4.11
A9: Standard Deviation | B9: 22.920369 | C9: Standard Deviation | D9: 7.237699 | E9: Standard Deviation | F9: 5.236939 | G9: Standard Deviation | H9: 3.9473684 | I9: Standard Deviation | J9: 4259.0035 | K9: Standard Deviation | L9: 0.53051775
A10: Sample Variance | B10: 525.34333 | C10: Sample Variance | D10: 52.384286 | E10: Sample Variance | F10: 27.42553 | G10: Sample Variance | H10: 15.581717 | I10: Sample Variance | J10: 18139111 | K10: Sample Variance | L10: 0.28144908
A11: Kurtosis | B11: -0.027891928 | C11: Kurtosis | D11: -0.59125634 | E11: Kurtosis | F11: 2.2843806 | G11: Kurtosis | H11: 0.11146248 | I11: Kurtosis | J11: 0.73627931 | K11: Kurtosis | L11: -0.23904427
A12: Skewness | B12: 0.020601127 | C12: Skewness | D12: 0.47511096 | E12: Skewness | F12: 1.503699 | G12: Skewness | H12: 0.21881565 | I12: Skewness | J12: 1.3691909 | K12: Skewness | L12: -0.73196466
A13: Range | B13: 116 | C13: Range | D13: 29.38 | E13: Range | F13: 24.5 | G13: Range | H13: 20 | I13: Range | J13: 14500 | K13: Range | L13: 2.31
A14: Minimum | B14: 20 | C14: Minimum | D14: 8 | E14: Minimum | F14: 0.5 | G14: Minimum | H14: 10 | I14: Minimum | J14: 500 | K14: Minimum | L14: 2.66
A15: Maximum | B15: 136 | C15: Maximum | D15: 37.38 | E15: Maximum | F15: 25 | G15: Maximum | H15: 30 | I15: Maximum | J15: 15000 | K15: Maximum | L15: 4.97
A16: Sum | B16: 7401 | C16: Sum | D16: 1836.69 | E16: Sum | F16: 537.5 | G16: Sum | H16: 1979 | I16: Sum | J16: 445870 | K16: Sum | L16: 422.79
A17: Count | B17: 100 | C17: Count | D17: 100 | E17: Count | F17: 100 | G17: Count | H17: 100 | I17: Count | J17: 100 | K17: Count | L17: 100
A19: Step 1.2 | B19: EDA Analysis for dependent variables
A20: monthly_revenue | D20: Bin | E20: Interval | F20: Bin | G20: Frequency | H20: %
D21: -25000 | E21: ="Less than (or =) " &D21 -> Less than (or =) -25000 | F21: -25000 | G21: 0 | H21: =G21/$G$36 -> 0
A22: Mean | B22: 78696.82 | D22: 0 | E22: ="Over "&D21&" to " & D22 -> Over -25000 to 0 | F22: 0 | G22: 0 | H22: =G22/$G$36 -> 0
A23: Standard Error | B23: 4002.4506 | D23: 25000 | E23: ="Over "&D22&" to " & D23 -> Over 0 to 25000 | F23: 25000 | G23: 1 | H23: =G23/$G$36 -> 0.01
A24: Median | B24: 70985 | D24: 50000 | E24: ="Over "&D23&" to " & D24 -> Over 25000 to 50000 | F24: 50000 | G24: 22 | H24: =G24/$G$36 -> 0.22
A25: Mode | B25: #N/A | D25: 75000 | E25: ="Over "&D24&" to " & D25 -> Over 50000 to 75000 | F25: 75000 | G25: 32 | H25: =G25/$G$36 -> 0.32
A26: Standard Deviation | B26: 40024.506 | D26: 100000 | E26: ="Over "&D25&" to " & D26 -> Over 75000 to 100000 | F26: 100000 | G26: 22 | H26: =G26/$G$36 -> 0.22
A27: Sample Variance | B27: 1.6019611e+09 | D27: 125000 | E27: ="Over "&D26&" to " & D27 -> Over 100000 to 125000 | F27: 125000 | G27: 13 | H27: =G27/$G$36 -> 0.13
A28: Kurtosis | B28: 4.2825092 | D28: 150000 | E28: ="Over "&D27&" to " & D28 -> Over 125000 to 150000 | F28: 150000 | G28: 6 | H28: =G28/$G$36 -> 0.06
A29: Skewness | B29: 1.7122707 | D29: 175000 | E29: ="Over "&D28&" to " & D29 -> Over 150000 to 175000 | F29: 175000 | G29: 1 | H29: =G29/$G$36 -> 0.01
A30: Range | B30: 224062 | D30: 200000 | E30: ="Over "&D29&" to " & D30 -> Over 175000 to 200000 | F30: 200000 | G30: 1 | H30: =G30/$G$36 -> 0.01
A31: Minimum | B31: 23275 | D31: 225000 | E31: ="Over "&D30&" to " & D31 -> Over 200000 to 225000 | F31: 225000 | G31: 0 | H31: =G31/$G$36 -> 0
A32: Maximum | B32: 247337 | D32: 250000 | E32: ="Over "&D31&" to " & D32 -> Over 225000 to 250000 | F32: 250000 | G32: 2 | H32: =G32/$G$36 -> 0.02
A33: Sum | B33: 7869682 | D33: 275000 | E33: ="Over "&D32&" to " & D33 -> Over 250000 to 275000 | F33: 275000 | G33: 0 | H33: =G33/$G$36 -> 0
A34: Count | B34: 100 | E34: ="Over "&D33 -> Over 275000 | F34: More | G34: 0 | H34: =G34/$G$36 -> 0
E36: Total | G36: =SUM(G21:G34) -> 100 | H36: =SUM(H21:H34) -> 1
A39: Step 2 | B39: Construct multiple linear regression model that includes all quantitative variables
A41: SUMMARY OUTPUT
A43: Regression Statistics
A44: Multiple R | B44: 0.54436106
A45: R Square | B45: 0.29632897
A46: Adjusted R Square | B46: 0.25093084
A47: Standard Error | B47: 34640.723
A48: Observations | B48: 100
...

Sheet Model_2_Full
A1: Step 1 | B1: Convert Qualitative data into "Dummy Variables", (Converted in rawdata Sheets)
A3: Step 2 | B3: Create a Correlation Matrix to identify the relationship between variables
A5: Correlation Matrix
B6: seating_capacity | C6: avg_meal_price | D6: years_in_business | E6: staff_count | F6: marketing_spend | G6: customer_rating | H6: monthly_revenue
A7: seating_capacity | B7: 1
A8: avg_meal_price | B8: 0.09993088 | C8: 1
A9: years_in_business | B9: -0.040407801 | C9: 0.0033235082 | D9: 1
A10: staff_count | B10: 0.77762417 | C10: 0.048505904 | D10: -0.036659424 | E10: 1
A11: marketing_spend | B11: 0.29095915 | C11: 0.06296475 | D11: -0.1672613 | E11: 0.16780288 | F11: 1
A12: customer_rating | B12: 0.040224152 | C12: -0.0021251796 | D12: 0.022653103 | E12: -0.056839945 | F12: 0.089833506 | G12: 1
A13: monthly_revenue | B13: 0.28790691 | C13: 0.2147843 | D13: 0.074820575 | E13: 0.37946596 | F13: 0.24979648 | G13: 0.23575036 | H13: 1
A15: Key Findings: | B15: seating_capacity and staff_count have high correlation (0.7776), either one of it needs to be removed as Excel’s limit on how many variables can be included
B16: seating_capacity contains 0 in the confidence interval, hence it is not statistically significant
B17: seating_capacity is removed in Model 2
A19: Step 3 | B19: Construct multiple linear regression model that includes all quantitative variables and qualitative variables (Excluding seating_capacity)
A21: SUMMARY OUTPUT
A23: Regression Statistics
A24: Multiple R | B24: 0.93330255
A25: R Square | B25: 0.87105364
A26: Adjusted R Square | B26: 0.84619651
A27: Standard Error | B27: 15696.726
A28: Observations | B28: 100
A30: ANOVA
B31: df | C31: SS | D31: MS | E31: F | F31: Significance F
A32: Regression | B32: 16 | C32: 1.3814401e+11 | D32: 8.6340008e+09 | E32: 35.042407 | F32: 3.7469269e-30
A33: Residual | B33: 83 | C33: 2.0450138e+10 | D33: 2.4638721e+08
A34: Total | B34: 99 | C34: 1.5859415e+11
B36: Coefficients | C36: Standard Error | D36: t Stat | E36: P-value | F36: Lower 95% | G36: Upper 95% | H36: Lower 95.0% | I36: Upper 95.0%
A37: Intercept | B37: -45317.94 | C37: 18982.12 | D37: -2.3874015 | E37: 0.01923985 | F37: -83072.613 | G37: -7563.2676 | H37: -83072.613 | I37: -7563.2676
A38: avg_meal_price | B38: 1400.3554 | C38: 229.64544 | D38: 6.097902 | E38: 3.2593166e-08 | F38: 943.59984 | G38: 1857.1109 | H38: 943.59984 | I38: 1857.1109
A39: years_in_business | B39: 1687.6424 | C39: 329.61286 | D39: 5.1200745 | E39: 1.945531e-06 | F39: 1032.0557 | G39: 2343.2291 | H39: 1032.0557 | I39: 2343.2291
A40: staff_count | B40: 2710.6106 | C40: 435.26945 | D40: 6.2274312 | E40: 1.8597077e-08 | F40: 1844.8772 | G40: 3576.344 | H40: 1844.8772 | I40: 3576.344
A41: marketing_spend | B41: 2.0903071 | C41: 0.41443294 | D41: 5.0437765 | E41: 2.6425355e-06 | F41: 1.2660167 | G41: 2.9145976 | H41: 1.2660167 | I41: 2.9145976
A42: customer_rating | B42: 18136.609 | C42: 3267.4344 | D42: 5.5507186 | E42: 3.3279591e-07 | F42: 11637.813 | G42: 24635.404 | H42: 11637.813 | I42: 24635.404
A43: location_type_Strip_Mall | B43: -21906.508 | C43: 4642.6354 | D43: -4.7185502 | E43: 9.5079281e-06 | F43: -31140.523 | G43: -12672.493 | H43: -31140.523 | I43: -12672.493
A44: location_type_Mall | B44: 14610.191 | C44: 4629.2086 | D44: 3.1560884 | E44: 0.0022284965 | F44: 5402.8818 | G44: 23817.501 | H44: 5402.8818 | I44: 23817.501
A45: location_type_Downtown | B45: 27633.371 | C45: 4582.0327 | D45: 6.0308105 | E45: 4.3518487e-08 | F45: 18519.892 | G45: 36746.85 | H45: 18519.892 | I45: 36746.85
A46: cuisine_type_Asian | B46: -17207.534 | C46: 5030.9606 | D46: -3.4203277 | E46: 0.00097245223 | F46: -27213.912 | G46: -7201.1558 | H46: -27213.912 | I46: -7201.1558
A47: cuisine_type_American | B47: -25114.561 | C47: 4799.275 | D47: -5.2329907 | E47: 1.2318983e-06 | F47: -34660.126 | G47: -15568.997 | H47: -34660.126 | I47: -15568.997
A48: cuisine_type_Italian | B48: -4800.5788 | C48: 5217.5062 | D48: -0.92009067 | E48: 0.36019182 | F48: -15177.989 | G48: 5576.8312 | H48: -15177.989 | I48: 5576.8312
...

Sheet Model_3_Improved
A1: Step 1 | B1: Convert dependent variables using log transformation
A3: ln(monthly_revenue) | D3: Bin | E3: Interval | F3: Bin | G3: Frequency | H3: %
D4: 9.75 | E4: ="Less than (or =) " & D4 -> Less than (or =) 9.75 | F4: 9.75 | G4: 0 | H4: =G4/$G$19 -> 0
A5: Mean | B5: 11.164212 | D5: 10 | E5: ="Over "&D4&" to " & D5 -> Over 9.75 to 10 | F5: 10 | G5: 0 | H5: =G5/$G$19 -> 0
A6: Standard Error | B6: 0.046266112 | D6: 10.25 | E6: ="Over "&D5&" to " & D6 -> Over 10 to 10.25 | F6: 10.25 | G6: 2 | H6: =G6/$G$19 -> 0.02
A7: Median | B7: 11.170214 | D7: 10.5 | E7: ="Over "&D6&" to " & D7 -> Over 10.25 to 10.5 | F7: 10.5 | G7: 2 | H7: =G7/$G$19 -> 0.02
A8: Mode | B8: #N/A | D8: 10.75 | E8: ="Over "&D7&" to " & D8 -> Over 10.5 to 10.75 | F8: 10.75 | G8: 18 | H8: =G8/$G$19 -> 0.18
A9: Standard Deviation | B9: 0.46266112 | D9: 11 | E9: ="Over "&D8&" to " & D9 -> Over 10.75 to 11 | F9: 11 | G9: 15 | H9: =G9/$G$19 -> 0.15
A10: Sample Variance | B10: 0.21405531 | D10: 11.25 | E10: ="Over "&D9&" to " & D10 -> Over 11 to 11.25 | F10: 11.25 | G10: 19 | H10: =G10/$G$19 -> 0.19
A11: Kurtosis | B11: -0.057624459 | D11: 11.5 | E11: ="Over "&D10&" to " & D11 -> Over 11.25 to 11.5 | F11: 11.5 | G11: 20 | H11: =G11/$G$19 -> 0.2
A12: Skewness | B12: 0.21507505 | D12: 11.75 | E12: ="Over "&D11&" to " & D12 -> Over 11.5 to 11.75 | F12: 11.75 | G12: 15 | H12: =G12/$G$19 -> 0.15
A13: Range | B13: 2.363372 | D13: 12 | E13: ="Over "&D12&" to " & D13 -> Over 11.75 to 12 | F13: 12 | G13: 5 | H13: =G13/$G$19 -> 0.05
A14: Minimum | B14: 10.055135 | D14: 12.25 | E14: ="Over "&D13&" to " & D14 -> Over 12 to 12.25 | F14: 12.25 | G14: 2 | H14: =G14/$G$19 -> 0.02
A15: Maximum | B15: 12.418507 | D15: 12.5 | E15: ="Over "&D14&" to " & D15 -> Over 12.25 to 12.5 | F15: 12.5 | G15: 2 | H15: =G15/$G$19 -> 0.02
A16: Sum | B16: 1116.4212 | D16: 12.75 | E16: ="Over "&D15&" to " & D16 -> Over 12.5 to 12.75 | F16: 12.75 | G16: 0 | H16: =G16/$G$19 -> 0
A17: Count | B17: 100 | E17: ="Over "&D16 -> Over 12.75 | F17: More | G17: 0 | H17: =G17/$G$19 -> 0
E19: Total | G19: =SUM(G4:G17) -> 100 | H19: =SUM(H4:H17) -> 1
A22: Step 2.1 | B22: Exclude seating_capacity in Model 3 because of high correlation with staff_count
A23: Step 2.2 | B23: Remove all variables that is not statistically significant in Model 2
B24: cuisine_type_Italian and has_parking_Yes is removed
A27: Step 3 | B27: Construct multiple linear regression model with ln(monthly_revenue) as dependant variable
A29: SUMMARY OUTPUT
A31: Regression Statistics
A32: Multiple R | B32: 0.96029458
A33: R Square | B33: 0.92216568
A34: Adjusted R Square | B34: 0.90934591
A35: Standard Error | B35: 0.13930179
A36: Observations | B36: 100
A38: ANOVA
B39: df | C39: SS | D39: MS | E39: F | F39: Significance F
A40: Regression | B40: 14 | C40: 19.542052 | D40: 1.3958609 | E40: 71.93309 | F40: 6.1110781e-41
A41: Residual | B41: 85 | C41: 1.6494241 | D41: 0.01940499
A42: Total | B42: 99 | C42: 21.191476
B44: Coefficients | C44: Standard Error | D44: t Stat | E44: P-value | F44: Lower 95% | G44: Upper 95% | H44: Lower 95.0% | I44: Upper 95.0%
A45: Intercept | B45: 9.5406298 | C45: 0.16208017 | D45: 58.863646 | E45: 1.1404146e-70 | F45: 9.218371 | G45: 9.8628886 | H45: 9.218371 | I45: 9.8628886
A46: avg_meal_price | B46: 0.021268359 | C46: 0.0019958693 | D46: 10.656188 | E46: 2.4777642e-17 | F46: 0.017300036 | G46: 0.025236682 | H46: 0.017300036 | I46: 0.025236682
A47: years_in_business | B47: 0.017461985 | C47: 0.0028798154 | D47: 6.063578 | E47: 3.5515212e-08 | F47: 0.011736141 | G47: 0.02318783 | H47: 0.011736141 | I47: 0.02318783
A48: staff_count | B48: 0.032360118 | C48: 0.0038591797 | D48: 8.3852321 | E48: 9.4683748e-13 | F48: 0.024687034 | G48: 0.040033201 | H48: 0.024687034 | I48: 0.040033201
A49: marketing_spend | B49: 2.7354175e-05 | C49: 3.6233066e-06 | D49: 7.549506 | E49: 4.5259405e-11 | F49: 2.0150071e-05 | G49: 3.455828e-05 | H49: 2.0150071e-05 | I49: 3.455828e-05
A50: customer_rating | B50: 0.20878701 | C50: 0.028918016 | D50: 7.2199631 | E50: 2.0447704e-10 | F50: 0.15129025 | G50: 0.26628377 | H50: 0.15129025 | I50: 0.26628377
...
